 2017-10-24 20:09:37,915 [P7696/D2/T1] INFO  Umbraco.Core.CoreBootManager - Umbraco 7.7.3 application starting on LIN16006880
 2017-10-24 20:09:37,933 [P7696/D2/T1] INFO  Umbraco.Core.PluginManager - Determining hash of code files on disk
 2017-10-24 20:09:37,949 [P7696/D2/T1] INFO  Umbraco.Core.PluginManager - Hash determined (took 15ms)
 2017-10-24 20:09:37,997 [P7696/D2/T1] INFO  Umbraco.Core.MainDom - Acquiring MainDom...
 2017-10-24 20:09:37,999 [P7696/D2/T1] INFO  Umbraco.Core.MainDom - Acquired MainDom.
 2017-10-24 20:09:38,002 [P7696/D2/T1] INFO  Umbraco.Core.PluginManager - Resolving umbraco.interfaces.IDiscoverable
 2017-10-24 20:09:38,176 [P7696/D2/T1] INFO  Umbraco.Core.PluginManager - Resolved umbraco.interfaces.IDiscoverable (took 174ms)
 2017-10-24 20:09:38,177 [P7696/D2/T1] INFO  Umbraco.Core.PluginManager - Resolving umbraco.interfaces.IApplicationStartupHandler
 2017-10-24 20:09:38,178 [P7696/D2/T1] INFO  Umbraco.Core.PluginManager - Resolved umbraco.interfaces.IApplicationStartupHandler (took 1ms)
 2017-10-24 20:09:38,221 [P7696/D2/T1] INFO  Umbraco.Core.PluginManager - Resolving umbraco.interfaces.IDiscoverable
 2017-10-24 20:09:38,221 [P7696/D2/T1] INFO  Umbraco.Core.PluginManager - Resolved umbraco.interfaces.IDiscoverable (took 0ms)
 2017-10-24 20:09:38,222 [P7696/D2/T1] INFO  Umbraco.Core.PluginManager - Resolving Umbraco.Core.PropertyEditors.IPropertyEditorValueConverter
 2017-10-24 20:09:38,223 [P7696/D2/T1] INFO  Umbraco.Core.PluginManager - Resolved Umbraco.Core.PropertyEditors.IPropertyEditorValueConverter (took 1ms)
 2017-10-24 20:09:38,225 [P7696/D2/T1] INFO  Umbraco.Core.PluginManager - Resolving umbraco.interfaces.IDiscoverable
 2017-10-24 20:09:38,228 [P7696/D2/T1] INFO  Umbraco.Core.PluginManager - Resolved umbraco.interfaces.IDiscoverable (took 2ms)
 2017-10-24 20:09:38,228 [P7696/D2/T1] INFO  Umbraco.Core.PluginManager - Resolving Umbraco.Core.PropertyEditors.IPropertyValueConverter
 2017-10-24 20:09:38,230 [P7696/D2/T1] INFO  Umbraco.Core.PluginManager - Resolved Umbraco.Core.PropertyEditors.IPropertyValueConverter (took 1ms)
 2017-10-24 20:09:38,245 [P7696/D2/T1] INFO  Umbraco.Core.PluginManager - Resolving umbraco.interfaces.IDiscoverable
 2017-10-24 20:09:38,245 [P7696/D2/T1] INFO  Umbraco.Core.PluginManager - Resolved umbraco.interfaces.IDiscoverable (took 0ms)
 2017-10-24 20:09:38,246 [P7696/D2/T1] INFO  Umbraco.Core.PluginManager - Resolving Umbraco.Web.Mvc.SurfaceController
 2017-10-24 20:09:38,247 [P7696/D2/T1] INFO  Umbraco.Core.PluginManager - Resolved Umbraco.Web.Mvc.SurfaceController (took 1ms)
 2017-10-24 20:09:38,248 [P7696/D2/T1] INFO  Umbraco.Core.PluginManager - Resolving umbraco.interfaces.IDiscoverable
 2017-10-24 20:09:38,249 [P7696/D2/T1] INFO  Umbraco.Core.PluginManager - Resolved umbraco.interfaces.IDiscoverable (took 0ms)
 2017-10-24 20:09:38,250 [P7696/D2/T1] INFO  Umbraco.Core.PluginManager - Resolving Umbraco.Web.WebApi.UmbracoApiController
 2017-10-24 20:09:38,251 [P7696/D2/T1] INFO  Umbraco.Core.PluginManager - Resolved Umbraco.Web.WebApi.UmbracoApiController (took 1ms)
 2017-10-24 20:09:55,182 [P7696/D2/T1] WARN  Umbraco.Core.Persistence.DbConnectionExtensions - Configured database is reporting as not being available! DataSource: IN-MUM-APPSONE1, InitialCatalog: RMSSecurity. Exception: System.Data.SqlClient.SqlException (0x80131904): A network-related or instance-specific error occurred while establishing a connection to SQL Server. The server was not found or was not accessible. Verify that the instance name is correct and that SQL Server is configured to allow remote connections. (provider: Named Pipes Provider, error: 40 - Could not open a connection to SQL Server) ---> System.ComponentModel.Win32Exception (0x80004005): The network path was not found
   at System.Data.SqlClient.SqlInternalConnectionTds..ctor(DbConnectionPoolIdentity identity, SqlConnectionString connectionOptions, SqlCredential credential, Object providerInfo, String newPassword, SecureString newSecurePassword, Boolean redirectedUserInstance, SqlConnectionString userConnectionOptions, SessionData reconnectSessionData, DbConnectionPool pool, String accessToken, Boolean applyTransientFaultHandling)
   at System.Data.SqlClient.SqlConnectionFactory.CreateConnection(DbConnectionOptions options, DbConnectionPoolKey poolKey, Object poolGroupProviderInfo, DbConnectionPool pool, DbConnection owningConnection, DbConnectionOptions userOptions)
   at System.Data.ProviderBase.DbConnectionFactory.CreatePooledConnection(DbConnectionPool pool, DbConnection owningObject, DbConnectionOptions options, DbConnectionPoolKey poolKey, DbConnectionOptions userOptions)
   at System.Data.ProviderBase.DbConnectionPool.CreateObject(DbConnection owningObject, DbConnectionOptions userOptions, DbConnectionInternal oldConnection)
   at System.Data.ProviderBase.DbConnectionPool.UserCreateRequest(DbConnection owningObject, DbConnectionOptions userOptions, DbConnectionInternal oldConnection)
   at System.Data.ProviderBase.DbConnectionPool.TryGetConnection(DbConnection owningObject, UInt32 waitForMultipleObjectsTimeout, Boolean allowCreate, Boolean onlyOneCheckConnection, DbConnectionOptions userOptions, DbConnectionInternal& connection)
   at System.Data.ProviderBase.DbConnectionPool.TryGetConnection(DbConnection owningObject, TaskCompletionSource`1 retry, DbConnectionOptions userOptions, DbConnectionInternal& connection)
   at System.Data.ProviderBase.DbConnectionFactory.TryGetConnection(DbConnection owningConnection, TaskCompletionSource`1 retry, DbConnectionOptions userOptions, DbConnectionInternal oldConnection, DbConnectionInternal& connection)
   at System.Data.ProviderBase.DbConnectionInternal.TryOpenConnectionInternal(DbConnection outerConnection, DbConnectionFactory connectionFactory, TaskCompletionSource`1 retry, DbConnectionOptions userOptions)
   at System.Data.ProviderBase.DbConnectionClosed.TryOpenConnection(DbConnection outerConnection, DbConnectionFactory connectionFactory, TaskCompletionSource`1 retry, DbConnectionOptions userOptions)
   at System.Data.SqlClient.SqlConnection.TryOpenInner(TaskCompletionSource`1 retry)
   at System.Data.SqlClient.SqlConnection.TryOpen(TaskCompletionSource`1 retry)
   at System.Data.SqlClient.SqlConnection.Open()
   at Umbraco.Core.Persistence.DbConnectionExtensions.IsAvailable(IDbConnection connection)
ClientConnectionId:00000000-0000-0000-0000-000000000000
Error Number:53,State:0,Class:20
 2017-10-24 20:09:55,183 [P7696/D2/T1] INFO  Umbraco.Core.DatabaseContext - CanConnect = False
 2017-10-24 20:09:55,293 [P7696/D2/T1] WARN  Umbraco.Core.Persistence.DbConnectionExtensions - Configured database is reporting as not being available! DataSource: IN-MUM-APPSONE1, InitialCatalog: RMSSecurity. Exception: System.Data.SqlClient.SqlException (0x80131904): A network-related or instance-specific error occurred while establishing a connection to SQL Server. The server was not found or was not accessible. Verify that the instance name is correct and that SQL Server is configured to allow remote connections. (provider: Named Pipes Provider, error: 40 - Could not open a connection to SQL Server) ---> System.ComponentModel.Win32Exception (0x80004005): The network path was not found
   at System.Data.ProviderBase.DbConnectionPool.TryGetConnection(DbConnection owningObject, UInt32 waitForMultipleObjectsTimeout, Boolean allowCreate, Boolean onlyOneCheckConnection, DbConnectionOptions userOptions, DbConnectionInternal& connection)
   at System.Data.ProviderBase.DbConnectionPool.TryGetConnection(DbConnection owningObject, TaskCompletionSource`1 retry, DbConnectionOptions userOptions, DbConnectionInternal& connection)
   at System.Data.ProviderBase.DbConnectionFactory.TryGetConnection(DbConnection owningConnection, TaskCompletionSource`1 retry, DbConnectionOptions userOptions, DbConnectionInternal oldConnection, DbConnectionInternal& connection)
   at System.Data.ProviderBase.DbConnectionInternal.TryOpenConnectionInternal(DbConnection outerConnection, DbConnectionFactory connectionFactory, TaskCompletionSource`1 retry, DbConnectionOptions userOptions)
   at System.Data.ProviderBase.DbConnectionClosed.TryOpenConnection(DbConnection outerConnection, DbConnectionFactory connectionFactory, TaskCompletionSource`1 retry, DbConnectionOptions userOptions)
   at System.Data.SqlClient.SqlConnection.TryOpenInner(TaskCompletionSource`1 retry)
   at System.Data.SqlClient.SqlConnection.TryOpen(TaskCompletionSource`1 retry)
   at System.Data.SqlClient.SqlConnection.Open()
   at Umbraco.Core.Persistence.DbConnectionExtensions.IsAvailable(IDbConnection connection)
ClientConnectionId:00000000-0000-0000-0000-000000000000
Error Number:53,State:0,Class:20
 2017-10-24 20:09:55,293 [P7696/D2/T1] INFO  Umbraco.Core.DatabaseContext - CanConnect = False
 2017-10-24 20:09:56,295 [P7696/D2/T1] WARN  Umbraco.Core.Persistence.DbConnectionExtensions - Configured database is reporting as not being available! DataSource: IN-MUM-APPSONE1, InitialCatalog: RMSSecurity. Exception: System.Data.SqlClient.SqlException (0x80131904): A network-related or instance-specific error occurred while establishing a connection to SQL Server. The server was not found or was not accessible. Verify that the instance name is correct and that SQL Server is configured to allow remote connections. (provider: Named Pipes Provider, error: 40 - Could not open a connection to SQL Server) ---> System.ComponentModel.Win32Exception (0x80004005): The network path was not found
   at System.Data.ProviderBase.DbConnectionPool.TryGetConnection(DbConnection owningObject, UInt32 waitForMultipleObjectsTimeout, Boolean allowCreate, Boolean onlyOneCheckConnection, DbConnectionOptions userOptions, DbConnectionInternal& connection)
   at System.Data.ProviderBase.DbConnectionPool.TryGetConnection(DbConnection owningObject, TaskCompletionSource`1 retry, DbConnectionOptions userOptions, DbConnectionInternal& connection)
   at System.Data.ProviderBase.DbConnectionFactory.TryGetConnection(DbConnection owningConnection, TaskCompletionSource`1 retry, DbConnectionOptions userOptions, DbConnectionInternal oldConnection, DbConnectionInternal& connection)
   at System.Data.ProviderBase.DbConnectionInternal.TryOpenConnectionInternal(DbConnection outerConnection, DbConnectionFactory connectionFactory, TaskCompletionSource`1 retry, DbConnectionOptions userOptions)
   at System.Data.ProviderBase.DbConnectionClosed.TryOpenConnection(DbConnection outerConnection, DbConnectionFactory connectionFactory, TaskCompletionSource`1 retry, DbConnectionOptions userOptions)
   at System.Data.SqlClient.SqlConnection.TryOpenInner(TaskCompletionSource`1 retry)
   at System.Data.SqlClient.SqlConnection.TryOpen(TaskCompletionSource`1 retry)
   at System.Data.SqlClient.SqlConnection.Open()
   at Umbraco.Core.Persistence.DbConnectionExtensions.IsAvailable(IDbConnection connection)
ClientConnectionId:00000000-0000-0000-0000-000000000000
Error Number:53,State:0,Class:20
 2017-10-24 20:09:56,301 [P7696/D2/T1] INFO  Umbraco.Core.DatabaseContext - CanConnect = False
 2017-10-24 20:09:57,303 [P7696/D2/T1] WARN  Umbraco.Core.Persistence.DbConnectionExtensions - Configured database is reporting as not being available! DataSource: IN-MUM-APPSONE1, InitialCatalog: RMSSecurity. Exception: System.Data.SqlClient.SqlException (0x80131904): A network-related or instance-specific error occurred while establishing a connection to SQL Server. The server was not found or was not accessible. Verify that the instance name is correct and that SQL Server is configured to allow remote connections. (provider: Named Pipes Provider, error: 40 - Could not open a connection to SQL Server) ---> System.ComponentModel.Win32Exception (0x80004005): The network path was not found
   at System.Data.ProviderBase.DbConnectionPool.TryGetConnection(DbConnection owningObject, UInt32 waitForMultipleObjectsTimeout, Boolean allowCreate, Boolean onlyOneCheckConnection, DbConnectionOptions userOptions, DbConnectionInternal& connection)
   at System.Data.ProviderBase.DbConnectionPool.TryGetConnection(DbConnection owningObject, TaskCompletionSource`1 retry, DbConnectionOptions userOptions, DbConnectionInternal& connection)
   at System.Data.ProviderBase.DbConnectionFactory.TryGetConnection(DbConnection owningConnection, TaskCompletionSource`1 retry, DbConnectionOptions userOptions, DbConnectionInternal oldConnection, DbConnectionInternal& connection)
   at System.Data.ProviderBase.DbConnectionInternal.TryOpenConnectionInternal(DbConnection outerConnection, DbConnectionFactory connectionFactory, TaskCompletionSource`1 retry, DbConnectionOptions userOptions)
   at System.Data.ProviderBase.DbConnectionClosed.TryOpenConnection(DbConnection outerConnection, DbConnectionFactory connectionFactory, TaskCompletionSource`1 retry, DbConnectionOptions userOptions)
   at System.Data.SqlClient.SqlConnection.TryOpenInner(TaskCompletionSource`1 retry)
   at System.Data.SqlClient.SqlConnection.TryOpen(TaskCompletionSource`1 retry)
   at System.Data.SqlClient.SqlConnection.Open()
   at Umbraco.Core.Persistence.DbConnectionExtensions.IsAvailable(IDbConnection connection)
ClientConnectionId:00000000-0000-0000-0000-000000000000
Error Number:53,State:0,Class:20
 2017-10-24 20:09:57,306 [P7696/D2/T1] INFO  Umbraco.Core.DatabaseContext - CanConnect = False
 2017-10-24 20:09:58,311 [P7696/D2/T1] WARN  Umbraco.Core.Persistence.DbConnectionExtensions - Configured database is reporting as not being available! DataSource: IN-MUM-APPSONE1, InitialCatalog: RMSSecurity. Exception: System.Data.SqlClient.SqlException (0x80131904): A network-related or instance-specific error occurred while establishing a connection to SQL Server. The server was not found or was not accessible. Verify that the instance name is correct and that SQL Server is configured to allow remote connections. (provider: Named Pipes Provider, error: 40 - Could not open a connection to SQL Server) ---> System.ComponentModel.Win32Exception (0x80004005): The network path was not found
   at System.Data.ProviderBase.DbConnectionPool.TryGetConnection(DbConnection owningObject, UInt32 waitForMultipleObjectsTimeout, Boolean allowCreate, Boolean onlyOneCheckConnection, DbConnectionOptions userOptions, DbConnectionInternal& connection)
   at System.Data.ProviderBase.DbConnectionPool.TryGetConnection(DbConnection owningObject, TaskCompletionSource`1 retry, DbConnectionOptions userOptions, DbConnectionInternal& connection)
   at System.Data.ProviderBase.DbConnectionFactory.TryGetConnection(DbConnection owningConnection, TaskCompletionSource`1 retry, DbConnectionOptions userOptions, DbConnectionInternal oldConnection, DbConnectionInternal& connection)
   at System.Data.ProviderBase.DbConnectionInternal.TryOpenConnectionInternal(DbConnection outerConnection, DbConnectionFactory connectionFactory, TaskCompletionSource`1 retry, DbConnectionOptions userOptions)
   at System.Data.ProviderBase.DbConnectionClosed.TryOpenConnection(DbConnection outerConnection, DbConnectionFactory connectionFactory, TaskCompletionSource`1 retry, DbConnectionOptions userOptions)
   at System.Data.SqlClient.SqlConnection.TryOpenInner(TaskCompletionSource`1 retry)
   at System.Data.SqlClient.SqlConnection.TryOpen(TaskCompletionSource`1 retry)
   at System.Data.SqlClient.SqlConnection.Open()
   at Umbraco.Core.Persistence.DbConnectionExtensions.IsAvailable(IDbConnection connection)
ClientConnectionId:00000000-0000-0000-0000-000000000000
Error Number:53,State:0,Class:20
 2017-10-24 20:09:58,313 [P7696/D2/T1] INFO  Umbraco.Core.DatabaseContext - CanConnect = False
 2017-10-24 20:09:59,314 [P7696/D2/T1] WARN  Umbraco.Core.Persistence.DbConnectionExtensions - Configured database is reporting as not being available! DataSource: IN-MUM-APPSONE1, InitialCatalog: RMSSecurity. Exception: System.Data.SqlClient.SqlException (0x80131904): A network-related or instance-specific error occurred while establishing a connection to SQL Server. The server was not found or was not accessible. Verify that the instance name is correct and that SQL Server is configured to allow remote connections. (provider: Named Pipes Provider, error: 40 - Could not open a connection to SQL Server) ---> System.ComponentModel.Win32Exception (0x80004005): The network path was not found
   at System.Data.ProviderBase.DbConnectionPool.TryGetConnection(DbConnection owningObject, UInt32 waitForMultipleObjectsTimeout, Boolean allowCreate, Boolean onlyOneCheckConnection, DbConnectionOptions userOptions, DbConnectionInternal& connection)
   at System.Data.ProviderBase.DbConnectionPool.TryGetConnection(DbConnection owningObject, TaskCompletionSource`1 retry, DbConnectionOptions userOptions, DbConnectionInternal& connection)
   at System.Data.ProviderBase.DbConnectionFactory.TryGetConnection(DbConnection owningConnection, TaskCompletionSource`1 retry, DbConnectionOptions userOptions, DbConnectionInternal oldConnection, DbConnectionInternal& connection)
   at System.Data.ProviderBase.DbConnectionInternal.TryOpenConnectionInternal(DbConnection outerConnection, DbConnectionFactory connectionFactory, TaskCompletionSource`1 retry, DbConnectionOptions userOptions)
   at System.Data.ProviderBase.DbConnectionClosed.TryOpenConnection(DbConnection outerConnection, DbConnectionFactory connectionFactory, TaskCompletionSource`1 retry, DbConnectionOptions userOptions)
   at System.Data.SqlClient.SqlConnection.TryOpenInner(TaskCompletionSource`1 retry)
   at System.Data.SqlClient.SqlConnection.TryOpen(TaskCompletionSource`1 retry)
   at System.Data.SqlClient.SqlConnection.Open()
   at Umbraco.Core.Persistence.DbConnectionExtensions.IsAvailable(IDbConnection connection)
ClientConnectionId:00000000-0000-0000-0000-000000000000
Error Number:53,State:0,Class:20
 2017-10-24 20:09:59,315 [P7696/D2/T1] INFO  Umbraco.Core.DatabaseContext - CanConnect = False
 2017-10-24 20:10:16,376 [P7696/D2/T1] WARN  Umbraco.Core.Persistence.DbConnectionExtensions - Configured database is reporting as not being available! DataSource: IN-MUM-APPSONE1, InitialCatalog: RMSSecurity. Exception: System.Data.SqlClient.SqlException (0x80131904): A network-related or instance-specific error occurred while establishing a connection to SQL Server. The server was not found or was not accessible. Verify that the instance name is correct and that SQL Server is configured to allow remote connections. (provider: Named Pipes Provider, error: 40 - Could not open a connection to SQL Server) ---> System.ComponentModel.Win32Exception (0x80004005): The network path was not found
   at System.Data.SqlClient.SqlInternalConnectionTds..ctor(DbConnectionPoolIdentity identity, SqlConnectionString connectionOptions, SqlCredential credential, Object providerInfo, String newPassword, SecureString newSecurePassword, Boolean redirectedUserInstance, SqlConnectionString userConnectionOptions, SessionData reconnectSessionData, DbConnectionPool pool, String accessToken, Boolean applyTransientFaultHandling)
   at System.Data.SqlClient.SqlConnectionFactory.CreateConnection(DbConnectionOptions options, DbConnectionPoolKey poolKey, Object poolGroupProviderInfo, DbConnectionPool pool, DbConnection owningConnection, DbConnectionOptions userOptions)
   at System.Data.ProviderBase.DbConnectionFactory.CreatePooledConnection(DbConnectionPool pool, DbConnection owningObject, DbConnectionOptions options, DbConnectionPoolKey poolKey, DbConnectionOptions userOptions)
   at System.Data.ProviderBase.DbConnectionPool.CreateObject(DbConnection owningObject, DbConnectionOptions userOptions, DbConnectionInternal oldConnection)
   at System.Data.ProviderBase.DbConnectionPool.UserCreateRequest(DbConnection owningObject, DbConnectionOptions userOptions, DbConnectionInternal oldConnection)
   at System.Data.ProviderBase.DbConnectionPool.TryGetConnection(DbConnection owningObject, UInt32 waitForMultipleObjectsTimeout, Boolean allowCreate, Boolean onlyOneCheckConnection, DbConnectionOptions userOptions, DbConnectionInternal& connection)
   at System.Data.ProviderBase.DbConnectionPool.TryGetConnection(DbConnection owningObject, TaskCompletionSource`1 retry, DbConnectionOptions userOptions, DbConnectionInternal& connection)
   at System.Data.ProviderBase.DbConnectionFactory.TryGetConnection(DbConnection owningConnection, TaskCompletionSource`1 retry, DbConnectionOptions userOptions, DbConnectionInternal oldConnection, DbConnectionInternal& connection)
   at System.Data.ProviderBase.DbConnectionInternal.TryOpenConnectionInternal(DbConnection outerConnection, DbConnectionFactory connectionFactory, TaskCompletionSource`1 retry, DbConnectionOptions userOptions)
   at System.Data.ProviderBase.DbConnectionClosed.TryOpenConnection(DbConnection outerConnection, DbConnectionFactory connectionFactory, TaskCompletionSource`1 retry, DbConnectionOptions userOptions)
   at System.Data.SqlClient.SqlConnection.TryOpenInner(TaskCompletionSource`1 retry)
   at System.Data.SqlClient.SqlConnection.TryOpen(TaskCompletionSource`1 retry)
   at System.Data.SqlClient.SqlConnection.Open()
   at Umbraco.Core.Persistence.DbConnectionExtensions.IsAvailable(IDbConnection connection)
ClientConnectionId:00000000-0000-0000-0000-000000000000
Error Number:53,State:0,Class:20
 2017-10-24 20:10:16,379 [P7696/D2/T1] INFO  Umbraco.Core.DatabaseContext - CanConnect = False
 2017-10-24 20:10:16,400 [P7696/D2/T1] ERROR Umbraco.Core.UmbracoApplicationBase - An unhandled exception occurred
Umbraco.Core.Exceptions.UmbracoStartupFailedException: Umbraco cannot start. A connection string is configured but Umbraco cannot connect to the database.
   at Umbraco.Core.CoreBootManager.EnsureDatabaseConnection()
   at Umbraco.Core.CoreBootManager.Complete(Action`1 afterComplete)
   at Umbraco.Web.WebBootManager.Complete(Action`1 afterComplete)
   at Umbraco.Core.UmbracoApplicationBase.StartApplication(Object sender, EventArgs e)
   at Umbraco.Core.UmbracoApplicationBase.Application_Start(Object sender, EventArgs e)
 2017-10-24 20:10:23,823 [P7696/D2/T11] ERROR UmbracoExamine.DataServices.UmbracoContentService - EXCEPTION OCCURRED reading GetAllUserPropertyNames
System.Data.SqlClient.SqlException (0x80131904): A network-related or instance-specific error occurred while establishing a connection to SQL Server. The server was not found or was not accessible. Verify that the instance name is correct and that SQL Server is configured to allow remote connections. (provider: Named Pipes Provider, error: 40 - Could not open a connection to SQL Server) ---> System.ComponentModel.Win32Exception (0x80004005): The network path was not found
   at System.Data.ProviderBase.DbConnectionPool.TryGetConnection(DbConnection owningObject, UInt32 waitForMultipleObjectsTimeout, Boolean allowCreate, Boolean onlyOneCheckConnection, DbConnectionOptions userOptions, DbConnectionInternal& connection)
   at System.Data.ProviderBase.DbConnectionPool.TryGetConnection(DbConnection owningObject, TaskCompletionSource`1 retry, DbConnectionOptions userOptions, DbConnectionInternal& connection)
   at System.Data.ProviderBase.DbConnectionFactory.TryGetConnection(DbConnection owningConnection, TaskCompletionSource`1 retry, DbConnectionOptions userOptions, DbConnectionInternal oldConnection, DbConnectionInternal& connection)
   at System.Data.ProviderBase.DbConnectionInternal.TryOpenConnectionInternal(DbConnection outerConnection, DbConnectionFactory connectionFactory, TaskCompletionSource`1 retry, DbConnectionOptions userOptions)
   at System.Data.ProviderBase.DbConnectionClosed.TryOpenConnection(DbConnection outerConnection, DbConnectionFactory connectionFactory, TaskCompletionSource`1 retry, DbConnectionOptions userOptions)
   at System.Data.SqlClient.SqlConnection.TryOpenInner(TaskCompletionSource`1 retry)
   at System.Data.SqlClient.SqlConnection.TryOpen(TaskCompletionSource`1 retry)
   at System.Data.SqlClient.SqlConnection.Open()
   at Umbraco.Core.Persistence.FaultHandling.RetryPolicy.<>c__DisplayClass20_0.<ExecuteAction>b__0()
   at Umbraco.Core.Persistence.FaultHandling.RetryPolicy.ExecuteAction[TResult](Func`1 func)
   at Umbraco.Core.Persistence.FaultHandling.RetryPolicy.ExecuteAction(Action action)
   at Umbraco.Core.Persistence.PetaPocoConnectionExtensions.OpenWithRetry(IDbConnection connection, RetryPolicy retryPolicy)
   at Umbraco.Core.Persistence.PetaPocoConnectionExtensions.OpenWithRetry(IDbConnection connection)
   at Umbraco.Core.Persistence.Database.OpenSharedConnection()
   at Umbraco.Core.Persistence.Database.BeginTransaction(IsolationLevel isolationLevel)
   at Umbraco.Core.Scoping.Scope.get_Database()
   at Umbraco.Core.DatabaseContext.get_Database()
   at UmbracoExamine.DataServices.UmbracoContentService.GetAllUserPropertyNames()
ClientConnectionId:00000000-0000-0000-0000-000000000000
Error Number:53,State:0,Class:20
 2017-10-24 20:10:23,973 [P7696/D2/T11] INFO  Umbraco.Core.MainDom - Stopping...
 2017-10-24 20:10:23,976 [P7696/D2/T11] INFO  Umbraco.Core.MainDom - Released MainDom.
